<?xml version="1.0"?>
<robot name="ALEX_Model_v2" xmlns:xacro="http://www.ros.org/wiki/xacro">

  <xacro:include filename="motor.xacro" ns="motor" />
  <xacro:include filename="common.xacro" ns="common" />
  <xacro:include filename="materials.xacro" />

  <xacro:property name="steeldensity" value="7850" />
  <xacro:property name="m_knee" value="5.77" />
  <xacro:property name="l_calf" value="0.425" />
  <xacro:property name="lgy_knee" value="0.2633" />
  <xacro:property name="l_ext" value="0.44" />
  <xacro:property name="m_ext" value="9.5870" />
  <xacro:property name="lgy_ext" value="0.1945" />
  <xacro:property name="lgx_leg" value="0.2095" />
  <xacro:property name="static_friction" value="10.4160" />

  <xacro:macro name="motor_dynamics">
      <dynamics damping="0" friction="${static_friction}" />
  </xacro:macro>

  <link name="world"></link>
  <link name="base">
    <xacro:common.box width="0.3" depth="0.05" height="0.5" density="${steeldensity}" />
  </link>

  <joint name="fix" type="fixed">
    <parent link="world" />
    <child link="base" />
    <origin xyz="0 0 1.5" rpy="0 0 0" />
  </joint>

  <xacro:macro name="point_mass" params="mass xyz">
    <inertial>
      <mass value="${mass}"/> 
      <inertia ixx="0.01" ixy="0.0" ixz="0.0" iyy="0.01" iyz="0.0" izz="0.01" />
      <origin xyz="${xyz}" />
    </inertial>
  </xacro:macro>

  <xacro:macro name="motor_cylinder" params="rpy">
    <visual>
      <material name="red" />
      <geometry>
        <cylinder length="0.05" radius="0.07" />
      </geometry>
      <origin rpy="${rpy}"/>
    </visual>
    <collision>
      <geometry>
        <cylinder length="0.05" radius="0.07" />
      </geometry>
      <origin rpy="${rpy}"/>
    </collision>
    <inertial>
      <origin rpy="${rpy}"/>
      <mass value="4" />
      <inertia ixx="0.1" ixy="0.0" ixz="0.0" iyy="0.1" iyz="0.0" izz="9.1617" />
    </inertial>
  </xacro:macro>

  <xacro:macro name="leg" params="prefix multiplier">
    <link name="${prefix}_abduction_link">
      <xacro:motor_cylinder rpy="${pi / 2} 0 0"/>
      <visual>
        <geometry>
          <box size="${lgx_leg} 0.05 0.05" />
        </geometry>
        <origin xyz="${multiplier * lgx_leg / 2} 0 0" />
      </visual>
      <visual>
        <geometry>
          <box size="0.2 0.05 0.05" />
        </geometry>
        <origin xyz="${multiplier * lgx_leg} -0.1 0" rpy="0 0 ${pi / 2}"/>
      </visual>
    </link>

    <link name="${prefix}_hip_link">
      <xacro:motor_cylinder rpy="0 ${pi / 2} 0"/>
      <visual>
        <geometry>
          <box size="0.05 0.05 ${l_ext}" />
        </geometry>
        <origin xyz="0 0 ${-1 * l_ext / 2}" />
      </visual>
      <xacro:point_mass mass="${m_ext}" xyz="0 0 ${-1 * lgy_ext}"/>
    </link>

    <joint name="${prefix}_hip" type="revolute">
      <parent link="${prefix}_abduction_link" />
      <child link="${prefix}_hip_link" />
      <origin xyz="${multiplier * lgx_leg} -0.2 0" rpy="0 0 0" />
      <limit lower="${-pi}" upper="${pi}" effort="100" velocity="100" />
      <axis xyz="${multiplier * -1} 0 0" />
      <xacro:motor_dynamics />
    </joint>

    <link name="${prefix}_knee_link">
      <xacro:motor_cylinder rpy="0 ${pi / 2} 0"/>
       <visual>
        <geometry>
          <box size="0.05 0.05 ${l_calf}" />
        </geometry>
        <origin xyz="0 0 ${-1 * l_calf / 2}"/>
      </visual>
      <xacro:point_mass mass="${m_knee}" xyz="0 0 ${-1 * lgy_knee}" />
    </link>

    <joint name="${prefix}_knee" type="revolute">
      <parent link="${prefix}_hip_link" />
      <child link="${prefix}_knee_link" />
      <origin xyz="0 0 ${-1 * l_ext}" rpy="0 0 0" />
      <limit lower="${-pi}" upper="${pi}" effort="100" velocity="100" />
      <axis xyz="${multiplier * -1} 0 0" />
      <xacro:motor_dynamics />
    </joint>
  </xacro:macro>

  <xacro:leg prefix="left" multiplier="1" />

  <joint name="left_abduction" type="revolute">
    <parent link="base" />
    <child link="left_abduction_link" />
    <origin xyz="0.15 0.05 -0.25" rpy="0 0 0" />
    <limit lower="${-pi / 2}" upper="${pi / 2}" effort="100" velocity="100" />
    <axis xyz="0 -1 0" />
    <xacro:motor_dynamics />
  </joint>
  
  <xacro:leg prefix="right" multiplier="-1" />

  <joint name="right_abduction" type="revolute">
    <parent link="base" />
    <child link="right_abduction_link" />
    <origin xyz="-0.15 0.05 -0.25" rpy="0 0 0" />
    <limit lower="${-pi / 2}" upper="${pi / 2}" effort="100" velocity="100" />
    <axis xyz="0 -1 0" />
    <xacro:motor_dynamics />
  </joint>

  <xacro:macro name="ros2control_motor" params="name">
    <joint name="${name}">
      <command_interface name="effort">
        <param name="min">-1000</param>
        <param name="max">1000</param>
      </command_interface>
      <state_interface name="position" />
      <state_interface name="velocity"/>
      <state_interface name="effort"/>
    </joint>
  </xacro:macro>

  <ros2_control name="GazeboSystem" type="system">
    <hardware>
      <plugin>gazebo_ros2_control/GazeboSystem</plugin>
    </hardware>
    <xacro:ros2control_motor name="left_abduction"/>
    <xacro:ros2control_motor name="right_abduction"/>
    <xacro:ros2control_motor name="left_hip"/>
    <xacro:ros2control_motor name="right_hip"/>
    <xacro:ros2control_motor name="left_knee"/>
    <xacro:ros2control_motor name="right_knee"/>
  </ros2_control>

  <gazebo>
    <plugin filename="libgazebo_ros2_control.so" name="gazebo_ros2_control">
      <parameters>../config/exo_controller.yaml</parameters>
    </plugin>
  </gazebo>
</robot>
