<?xml version="1.0"?>
<robot name="ALEX_Model_v2" xmlns:xacro="http://www.ros.org/wiki/xacro">

  <xacro:include filename="motor.xacro" ns="motor" />
  <xacro:include filename="common.xacro" ns="common" />
  <xacro:include filename="materials.xacro" />

  <!-- x = left, y = robot back, z = up -->
  <link name="world"></link>

  <link name="base">
    <xacro:common.box width="0.2" depth="0.2" height="0.2" density="100" />
  </link>

  <joint name="fix" type="fixed">
    <parent link="world" />
    <child link="base" />
    <origin xyz="0 0 0.5" rpy="0 0 0" />
  </joint>

  <link name="propellor">
    <xacro:common.cylinder length="0.1" radius="0.01" density="100" rpy="${pi / 2} 0 0" />
  </link>

  <joint name="propellor_joint" type="revolute">
    <parent link="base" />
    <child link="propellor" />
    <origin xyz="0 -0.15 0" />
    <limit lower="${-100 * pi}" upper="${100 * pi}" effort="100000" velocity="1000000" />
    <axis xyz="0 1 0" />
    <dynamics damping="1" friction="0.1" />
  </joint>

  <link name="pendulum_mass">
    <xacro:common.cylinder length="0.3" radius="0.01" density="10000" />
  </link>

  <joint name="pendulum_joint" type="fixed">
    <parent link="propellor" />
    <child link="pendulum_mass" />
    <origin xyz="0 -0.05 0.15" />
  </joint>

  <ros2_control name="GazeboSystem" type="system">
    <hardware>
      <plugin>gazebo_ros2_control/GazeboSystem</plugin>
    </hardware>
    <joint name="propellor_joint">
      <command_interface name="effort">
        <param name="min">-1000</param>
        <param name="max">1000</param>
      </command_interface>
      <state_interface name="position" />
      <state_interface name="velocity"/>
      <state_interface name="effort"/>
    </joint>
  </ros2_control>

  <gazebo>
    <plugin filename="libgazebo_ros2_control.so" name="gazebo_ros2_control">
      <parameters>../config/motor_controller.yaml</parameters>
    </plugin>
  </gazebo>

</robot>
